Workbook

Sheet Szállítólevél
L2: =C5 -> 46092 | T2: 1
C3: Példány: …... / 4
C4: mint Megbízó 1117 Budapest, Galvani utca 44. Adószám: 32082230-2-43
C5: 46092
C6: Szállítólevél
C8: Keletkezési hely | O8: Fogadó létesítmény
C10: Hulladék keletkezési helye* (cég név) | G10: MAGMA Kft. | O10: Fogadó létesítmény neve* | S10: Kappa Star Recycling Hungary Kft.
C11: Hulladék keletkezési helye* (település név) | G11: 1211 Budapest, Déli utca 13.
C12: Járatszám1 | G12: IIH-493
C13: Amennyiben létesítményből kerül kiszállításra:
C14: Átadó létesítmény címe2 | O14: Fogadó létesítmény címe* | S14: 1214 Budapest, Mag utca 3.
C15: Átadó létesítmény típusa2 | G15: =IF(G14>0,VLOOKUP(G14,#REF!,2,FALSE)," ") | O15: Fogadó létesítmény típusa* | S15: előkezelő
C16: Átadó létesítmény KTJ azonosítója2 | G16: =IF(G14>0,VLOOKUP(G15,#REF!,3,FALSE)," ") | O16: Fogadó létesítmény KTJ azonosítója* | S16: 101 369 254
C18: Szállító partner
C19: MOHU Zrt-vel szerződött szállító partner neve: | N19: Kappa Star Recycling Hungary Kft.
C20: MOHU Zrt-vel szerződött szállító partner székhelye: | N20: 1214 Budapest, Mag utca 3.
C21: Szállító partner közreműködő neve: | N21: =G10 -> MAGMA Kft.
C22: Szállító partner közreműködő székhelye: | N22: =G11 -> 1211 Budapest, Déli utca 13.
C23: Szállító jármű azonosítója (gk. rendszám)* | N23: =G12 -> IIH-493
C24: Szállító jármű azonosítója (pótrendszám)3 | N24: -
C25: Szállítás célja* | N25: előkezelés
C27: Szállítás módja*: | H27:  Begyűjtés  Áttárolás
C29: Begyűjtés esetén a hulladék eredete:  Lakossági közszolgáltatói résztevékenység  Intézményi közszolgáltatói résztevékenység  Lakossági intézményi résztevékenység  Intézményi intézményi résztevékenység  Összevont résztevékenység  Illegális  Köztisztasági  Minőségi kifogás okán visszaszállított | K29: Begyűjtés esetén a gyűjtés módja:  Vegyes gyűjtés  Házhoz menő elkülönített gyűjtés  Hulladékgyűjtő sziget  Egyéb gyűjtőhely  EPR egyéni teljesítő  Lomtalanítás  DRS
C30: Szállítmány
C31: Megrendelés száma* | D31: Hulladék típusa (HAK)* | G31: Hulladék specifikációja (megnevezés)* | J31: Göngyöleg | T31: Hulladék mennyisége (nettó)*
J32: Megnevezés* | P32: Mennyiség* | R32: Mennyiség egység (kg/t/db)*
C33: - | D33: =IF($J33>0,VLOOKUP($J33,'Specifikáció segédlet'!A:C,3,FALSE),"") -> 15 01 01 | G33: =IF($J33>0,VLOOKUP($J33,'Specifikáció segédlet'!A:C,2,FALSE),"") -> Papír és karton csomagolás hulladéka (EPR) | J33: Papír hulladék hullámkarton ömlesztett intézményi | P33: ömlesztett | R33: -
C34: =IF(J34>0,"-","") | D34: =IF($J34>0,VLOOKUP($J34,'Specifikáció segédlet'!A:C,3,FALSE),"") | G34: =IF($J34>0,VLOOKUP($J34,'Specifikáció segédlet'!A:C,2,FALSE),"") | P34: =IF(J34>0,"ömlesztett","")
C35: =IF(J35>0,"-","") | D35: =IF($J35>0,VLOOKUP($J35,'Specifikáció segédlet'!A:C,3,FALSE),"") | G35: =IF($J35>0,VLOOKUP($J35,'Specifikáció segédlet'!A:C,2,FALSE),"") | P35: =IF(J35>0,"ömlesztett","")
K36: =L2 -> 46092 | T36: =T2 -> 1
C37: Példány: …... / 4
C38: mint Megbízó 1117 Budapest, Galvani utca 44. Adószám: 32082230-2-43
F40: Név | Q40: Aláírás
C41: Átadó/Szállító: | F41: =G10 -> MAGMA Kft.
C42: Átvevő: | F42: Kappa Star Recycling Hungary Kft.
Q44: Dátum
L45: Megrendelés dátuma* | Q45: =Q46 -> 46092
L46: Teljesítés kelte* | Q46: =C5 -> 46092
B47: Kitöltési útmutató
B48: * kötelezően kitöltendő 1 hulladék begyűjtés esetén kötelezően kitöltendő 2 létesítmények közötti szállítás esetén kötelezően kitöltendő 3 pótkocsis szállítás esetén kötelezően kitöltendő
...

Sheet Specifikáció segédlet
A1: Megnevezés* | B1: Hulladék specifikációja (megnevezés)* | C1: Hulladék típusa (HAK)*
A2: LDPE fólia hulladék natúr 95/5 ömlesztett intézményi | B2: Műanyag csomagolás hulladéka (EPR) | C2: 15 01 02
A3: LDPE fólia hulladék natúr 80/20 ömlesztett intézményi | B3: Műanyag csomagolás hulladéka (EPR) | C3: 15 01 02
A4: LDPE fólia hulladék színes 60/40 ömlesztett intézményi | B4: Műanyag csomagolás hulladéka (EPR) | C4: 15 01 02
A5: Papír hulladék hullámkarton ömlesztett intézményi | B5: Papír és karton csomagolás hulladéka (EPR) | C5: 15 01 01
A6: Papír hulladék reklámhordozó öml int | B6: Reklámhordozó papír hulladéka (EPR) | C6: 20 01 01
A7: Papír hulladék vegyes ömlesztett, intézményi | B7: Települési hulladékok | C7: 20 01 01
